<?xml version="1.0" encoding="utf-8"?>
<!-- This URDF was automatically created by SolidWorks to URDF Exporter! Originally created by Stephen Brawner (brawner@gmail.com) 
     Commit Version: 1.6.0-4-g7f85cfe  Build Version: 1.6.7995.38578
     For more information, please see http://wiki.ros.org/sw_urdf_exporter -->
<robot
  name="scara_urdf">
  <link
    name="base">
    <inertial>
      <origin
        xyz="1.1102E-16 1.1102E-16 0.016963"
        rpy="0 0 0" />
      <mass
        value="0.81356" />
      <inertia
        ixx="0.0017034"
        ixy="2.3161E-20"
        ixz="-7.2992E-19"
        iyy="0.0017034"
        iyz="1.1526E-18"
        izz="0.0031874" />
    </inertial>
    <visual>
      <origin
        xyz="0 0 0"
        rpy="0 0 0" />
      <geometry>
        <mesh
          filename="package://scara_urdf/meshes/base.STL" />
      </geometry>
      <material
        name="">
        <color
          rgba="0.9098 0.44314 0.031373 1" />
      </material>
    </visual>
    <collision>
      <origin
        xyz="0 0 0"
        rpy="0 0 0" />
      <geometry>
        <mesh
          filename="package://scara_urdf/meshes/base.STL" />
      </geometry>
    </collision>
  </link>
  <link
    name="M1">
    <inertial>
      <origin
        xyz="-1.1102E-16 1.1102E-16 0.075"
        rpy="0 0 0" />
      <mass
        value="1.6696" />
      <inertia
        ixx="0.0077803"
        ixy="-2.0605E-34"
        ixz="2.1121E-34"
        iyy="0.0077803"
        iyz="-5.294E-21"
        izz="0.0032888" />
    </inertial>
    <visual>
      <origin
        xyz="0 0 0"
        rpy="0 0 0" />
      <geometry>
        <mesh
          filename="package://scara_urdf/meshes/M1.STL" />
      </geometry>
      <material
        name="">
        <color
          rgba="1 1 0 1" />
      </material>
    </visual>
    <collision>
      <origin
        xyz="0 0 0"
        rpy="0 0 0" />
      <geometry>
        <mesh
          filename="package://scara_urdf/meshes/M1.STL" />
      </geometry>
    </collision>
  </link>
  <joint
    name="Joint1"
    type="continuous">
    <origin
      xyz="0 0 0.06"
      rpy="0 0 0" />
    <parent
      link="base" />
    <child
      link="M1" />
    <axis
      xyz="0 0 -1" />
  </joint>
  <link
    name="M2">
    <inertial>
      <origin
        xyz="0.081749 -0.0069094 0.030511"
        rpy="0 0 0" />
      <mass
        value="0.71062" />
      <inertia
        ixx="0.00039441"
        ixy="0.00026417"
        ixz="1.5922E-06"
        iyy="0.0034975"
        iyz="-1.3456E-07"
        izz="0.0038467" />
    </inertial>
    <visual>
      <origin
        xyz="0 0 0"
        rpy="0 0 0" />
      <geometry>
        <mesh
          filename="package://scara_urdf/meshes/M2.STL" />
      </geometry>
      <material
        name="">
        <color
          rgba="0.75294 0.75294 0.75294 1" />
      </material>
    </visual>
    <collision>
      <origin
        xyz="0 0 0"
        rpy="0 0 0" />
      <geometry>
        <mesh
          filename="package://scara_urdf/meshes/M2.STL" />
      </geometry>
    </collision>
  </link>
  <joint
    name="Joint2"
    type="continuous">
    <origin
      xyz="0 0 0.18"
      rpy="0 0 0" />
    <parent
      link="M1" />
    <child
      link="M2" />
    <axis
      xyz="0 0 1" />
    <limit
      lower="0"
      upper="0"
      effort="0"
      velocity="0" />
  </joint>
  <link
    name="M3">
    <inertial>
      <origin
        xyz="0.047629 0.020812 0.072612"
        rpy="0 0 0" />
      <mass
        value="0.99972" />
      <inertia
        ixx="0.0017827"
        ixy="-0.001154"
        ixz="0.00043198"
        iyy="0.0039194"
        iyz="0.00018876"
        izz="0.0042708" />
    </inertial>
    <visual>
      <origin
        xyz="0 0 0"
        rpy="0 0 0" />
      <geometry>
        <mesh
          filename="package://scara_urdf/meshes/M3.STL" />
      </geometry>
      <material
        name="">
        <color
          rgba="0.75294 0.75294 0.75294 1" />
      </material>
    </visual>
    <collision>
      <origin
        xyz="0 0 0"
        rpy="0 0 0" />
      <geometry>
        <mesh
          filename="package://scara_urdf/meshes/M3.STL" />
      </geometry>
    </collision>
  </link>
  <joint
    name="Joint3"
    type="continuous">
    <origin
      xyz="0.19929 -0.016844 0.0425"
      rpy="0 0 0" />
    <parent
      link="M2" />
    <child
      link="M3" />
    <axis
      xyz="0 0 -1" />
    <limit
      lower="0"
      upper="0"
      effort="0"
      velocity="0" />
  </joint>
  <link
    name="M4R">
    <inertial>
      <origin
        xyz="1.4784E-10 -1.9373E-10 0.15749"
        rpy="0 0 0" />
      <mass
        value="0.10305" />
      <inertia
        ixx="0.0014027"
        ixy="9.2614E-10"
        ixz="-2.3549E-12"
        iyy="0.0014027"
        iyz="3.0832E-12"
        izz="4.2483E-06" />
    </inertial>
    <visual>
      <origin
        xyz="0 0 0"
        rpy="0 0 0" />
      <geometry>
        <mesh
          filename="package://scara_urdf/meshes/M4R.STL" />
      </geometry>
      <material
        name="">
        <color
          rgba="1 0 1 1" />
      </material>
    </visual>
    <collision>
      <origin
        xyz="0 0 0"
        rpy="0 0 0" />
      <geometry>
        <mesh
          filename="package://scara_urdf/meshes/M4R.STL" />
      </geometry>
    </collision>
  </link>
  <joint
    name="Joint4Rotate"
    type="continuous">
    <origin
      xyz="0.13745 0.060061 0.0925"
      rpy="3.1416 0 0" />
    <parent
      link="M3" />
    <child
      link="M4R" />
    <axis
      xyz="0 0 -1" />
  </joint>
  <link
    name="M4L">
    <inertial>
      <origin
        xyz="1.4784E-10 -1.9373E-10 0.15749"
        rpy="0 0 0" />
      <mass
        value="0.10305" />
      <inertia
        ixx="0.0014027"
        ixy="9.2614E-10"
        ixz="-2.3549E-12"
        iyy="0.0014027"
        iyz="3.0832E-12"
        izz="4.2483E-06" />
    </inertial>
    <visual>
      <origin
        xyz="0 0 0"
        rpy="0 0 0" />
      <geometry>
        <mesh
          filename="package://scara_urdf/meshes/M4L.STL" />
      </geometry>
      <material
        name="">
        <color
          rgba="1 0 1 1" />
      </material>
    </visual>
    <collision>
      <origin
        xyz="0 0 0"
        rpy="0 0 0" />
      <geometry>
        <mesh
          filename="package://scara_urdf/meshes/M4L.STL" />
      </geometry>
    </collision>
  </link>
  <joint
    name="Joint4Linear"
    type="prismatic">
    <origin
      xyz="0.13745 0.060061 0.0925"
      rpy="3.1416 0 0" />
    <parent
      link="M3" />
    <child
      link="M4L" />
    <axis
      xyz="0 0 -1" />
    <limit
      lower="0"
      upper="0"
      effort="0"
      velocity="0" />
  </joint>
</robot>
