<?xml version='1.0' encoding='UTF-8'?>
<!-- This URDF was automatically created by SolidWorks to URDF Exporter! Originally created by Stephen Brawner (brawner@gmail.com) 
     Commit Version: 1.6.0-4-g7f85cfe  Build Version: 1.6.7995.38578
     For more information, please see http://wiki.ros.org/sw_urdf_exporter -->
<robot name="baugruppe_arti4">
  <link name="base_link">
    <inertial>
      <origin xyz="0.00435229897106417 1.19101823147447E-06 0.206310280142742" rpy="0 0 0"/>
      <mass value="118.32754627267"/>
      <inertia ixx="4.47689007324204" ixy="4.43639388222346E-05" ixz="-0.282702973308682" iyy="4.82074220348992" iyz="2.31671022438448E-05" izz="5.23809069840615"/>
    </inertial>
    <visual>
      <origin xyz="0 0 0" rpy="0 0 0"/>
      <geometry>
        <mesh filename="package://baugruppe_arti4/meshes/base_link.STL"/>
      </geometry>
      <material name="">
        <color rgba="0.909803921568627 0.443137254901961 0.0313725490196078 1"/>
      </material>
    </visual>
    <collision>
      <origin xyz="0 0 0" rpy="0 0 0"/>
      <geometry>
        <mesh filename="package://baugruppe_arti4/meshes/base_link.STL"/>
      </geometry>
    </collision>
  </link>
  <link name="achse1">
    <inertial>
      <origin xyz="6.93889390390723E-18 -0.11465842559516 -5.0349895881356E-17" rpy="0 0 0"/>
      <mass value="37.2990953823488"/>
      <inertia ixx="1.58478276326517" ixy="6.72682473106839E-17" ixz="2.56697693671266E-07" iyy="1.78904675337478" iyz="-3.48174136545842E-17" izz="0.790434634778931"/>
    </inertial>
    <visual>
      <origin xyz="0 0 0" rpy="0 0 0"/>
      <geometry>
        <mesh filename="package://baugruppe_arti4/meshes/achse1.STL"/>
      </geometry>
      <material name="">
        <color rgba="1 1 0 1"/>
      </material>
    </visual>
    <collision>
      <origin xyz="0 0 0" rpy="0 0 0"/>
      <geometry>
        <mesh filename="package://baugruppe_arti4/meshes/achse1.STL"/>
      </geometry>
    </collision>
  </link>
  <joint name="achse1_1" type="continuous">
    <origin xyz="0.0350000000000001 0 0.452" rpy="-1.5707963267949 0 0"/>
    <parent link="base_link"/>
    <child link="achse1"/>
    <axis xyz="0 1 0"/>
  </joint>
  <link name="achse2">
    <inertial>
      <origin xyz="-0.20000241917792 2.17580123362815E-09 1.95958403433266E-06" rpy="0 0 0"/>
      <mass value="50.198715025992"/>
      <inertia ixx="1.10727917154317" ixy="-2.41399858669304E-07" ixz="2.94734339886711E-11" iyy="1.40197024292102" iyz="-2.64709386633196E-07" izz="0.879798937506276"/>
    </inertial>
    <visual>
      <origin xyz="0 0 0" rpy="0 0 0"/>
      <geometry>
        <mesh filename="package://baugruppe_arti4/meshes/achse2.STL"/>
      </geometry>
      <material name="">
        <color rgba="0 1 0 1"/>
      </material>
    </visual>
    <collision>
      <origin xyz="0 0 0" rpy="0 0 0"/>
      <geometry>
        <mesh filename="package://baugruppe_arti4/meshes/achse2.STL"/>
      </geometry>
    </collision>
  </link>
  <joint name="achse2_1" type="continuous">
    <origin xyz="0 -0.2 0" rpy="-3.14159265358979 0 1.5707963267949"/>
    <parent link="achse1"/>
    <child link="achse2"/>
    <axis xyz="0 0 1"/>
  </joint>
  <link name="achse3">
    <inertial>
      <origin xyz="-0.191833083805588 -1.9595890479206E-06 -2.77555756156289E-17" rpy="0 0 0"/>
      <mass value="39.4811032739565"/>
      <inertia ixx="1.95192669647927" ixy="-1.73409535332591E-16" ixz="-2.12396957990674E-16" iyy="1.72974079833023" iyz="2.16840434497101E-16" izz="3.29933055799716"/>
    </inertial>
    <visual>
      <origin xyz="0 0 0" rpy="0 0 0"/>
      <geometry>
        <mesh filename="package://baugruppe_arti4/meshes/achse3.STL"/>
      </geometry>
      <material name="">
        <color rgba="0 1 1 1"/>
      </material>
    </visual>
    <collision>
      <origin xyz="0 0 0" rpy="0 0 0"/>
      <geometry>
        <mesh filename="package://baugruppe_arti4/meshes/achse3.STL"/>
      </geometry>
    </collision>
  </link>
  <joint name="achse3_1" type="continuous">
    <origin xyz="-0.400000000000001 0 0" rpy="-1.5707963267949 0 0"/>
    <parent link="achse2"/>
    <child link="achse3"/>
    <axis xyz="0 1 0"/>
  </joint>
  <link name="achse4">
    <inertial>
      <origin xyz="0.057535307950419 0.0411539935888574 1.95958904790402E-06" rpy="0 0 0"/>
      <mass value="75.8024522154093"/>
      <inertia ixx="2.44855643577337" ixy="-0.362721911973878" ixz="8.23601090278812E-18" iyy="2.69457704418384" iyz="1.68922518611178E-16" izz="2.71260798797946"/>
    </inertial>
    <visual>
      <origin xyz="0 0 0" rpy="0 0 0"/>
      <geometry>
        <mesh filename="package://baugruppe_arti4/meshes/achse4.STL"/>
      </geometry>
      <material name="">
        <color rgba="0 0 1 1"/>
      </material>
    </visual>
    <collision>
      <origin xyz="0 0 0" rpy="0 0 0"/>
      <geometry>
        <mesh filename="package://baugruppe_arti4/meshes/achse4.STL"/>
      </geometry>
    </collision>
  </link>
  <joint name="achse4_1" type="continuous">
    <origin xyz="-0.399999999999999 0 0" rpy="1.5707963267949 -1.5707963267949 0"/>
    <parent link="achse3"/>
    <child link="achse4"/>
    <axis xyz="0 0 1"/>
  </joint>
  <link name="achse5">
    <inertial>
      <origin xyz="-1.80193934313788E-05 0.000118318329248121 0.164175255546401" rpy="0 0 0"/>
      <mass value="12.062537692943"/>
      <inertia ixx="0.322800598748907" ixy="-2.61435617459413E-08" ixz="-3.40682810523782E-05" iyy="0.258394199817323" iyz="0.000121923317188701" izz="0.223448646036243"/>
    </inertial>
    <visual>
      <origin xyz="0 0 0" rpy="0 0 0"/>
      <geometry>
        <mesh filename="package://baugruppe_arti4/meshes/achse5.STL"/>
      </geometry>
      <material name="">
        <color rgba="1 0 1 1"/>
      </material>
    </visual>
    <collision>
      <origin xyz="0 0 0" rpy="0 0 0"/>
      <geometry>
        <mesh filename="package://baugruppe_arti4/meshes/achse5.STL"/>
      </geometry>
    </collision>
  </link>
  <joint name="achse5_1" type="continuous">
    <origin xyz="0.318896988774263 0.141654099261087 0" rpy="-1.5707963267949 0 -1.5707963267949"/>
    <parent link="achse4"/>
    <child link="achse5"/>
    <axis xyz="0 0 1"/>
  </joint>
  <link name="achse6">
    <inertial>
      <origin xyz="-0.0103023778101935 -1.48497864755232E-06 6.66133814775094E-16" rpy="0 0 0"/>
      <mass value="11.7787579135722"/>
      <inertia ixx="0.110992482917872" ixy="9.37468004942909E-18" ixz="1.78551536412936E-18" iyy="0.127560903807858" iyz="3.58438038934541E-18" izz="0.121824672671966"/>
    </inertial>
    <visual>
      <origin xyz="0 0 0" rpy="0 0 0"/>
      <geometry>
        <mesh filename="package://baugruppe_arti4/meshes/achse6.STL"/>
      </geometry>
      <material name="">
        <color rgba="0.501960784313725 0.501960784313725 0.501960784313725 1"/>
      </material>
    </visual>
    <collision>
      <origin xyz="0 0 0" rpy="0 0 0"/>
      <geometry>
        <mesh filename="package://baugruppe_arti4/meshes/achse6.STL"/>
      </geometry>
    </collision>
  </link>
  <joint name="achse6_1" type="continuous">
    <origin xyz="0 0 0.305281304512374" rpy="0 1.5707963267949 0"/>
    <parent link="achse5"/>
    <child link="achse6"/>
    <axis xyz="0 1 0"/>
  </joint>
</robot>
